<?xml version="1.0"?>
<robot xmlns:xacro="http://www.ros.org/wiki/xacro" name="two_link_manipulator">
    <!-- メカ構造の定義 -->
    <link name="world"/>

    <!-- worldとbase_linkを固定するジョイント -->
    <joint name="fixed" type="fixed">
        <parent link="world"/>
        <child link="base_link"/>
        <origin xyz="0 0 0.15" rpy="0 0 0"/>
    </joint>

    <!-- ベースリンク -->
    <link name="base_link">
        <visual>
            <geometry>
                <cylinder radius="0.1" length="0.3"/>
            </geometry>
            <material name="gray">
                <color rgba="0.5 0.5 0.5 1"/>
            </material>
        </visual>
        <collision>
            <geometry>
                <cylinder radius="0.1" length="0.3"/>
            </geometry>
        </collision>
        <inertial>
            <mass value="1.0"/>
            <inertia ixx="0.01" ixy="0" ixz="0" iyy="0.01" iyz="0" izz="0.01"/>
        </inertial>
    </link>

    <gazebo reference="base_link">
        <material>Gazebo/Gray</material>
    </gazebo>

    <!-- リンク1 -->
    <link name="link1">
        <visual>
            <geometry>
                <box size="0.5 0.1 0.1"/>
            </geometry>
            <origin xyz="0.25 0 0" rpy="0 0 0"/>
            <material name="blue">
                <color rgba="0 0 1 1"/>
            </material>
        </visual>
        <collision>
            <geometry>
                <box size="0.5 0.1 0.1"/>
            </geometry>
            <origin xyz="0.25 0 0" rpy="0 0 0"/>
        </collision>
        <inertial>
            <mass value="1.0"/>
            <origin xyz="0.25 0 0" rpy="0 0 0"/>
            <inertia ixx="0.01" ixy="0" ixz="0" iyy="0.01" iyz="0" izz="0.01"/>
        </inertial>
    </link>

    <gazebo reference="link1">
        <material>Gazebo/Blue</material>
    </gazebo>

    <!-- リンク2 -->
    <link name="link2">
        <visual>
            <geometry>
                <box size="0.5 0.1 0.08"/>
            </geometry>
            <origin xyz="0.1 0 0" rpy="0 0 0"/>
            <material name="red">
                <color rgba="1 0 0 1"/>
            </material>
        </visual>
        <collision>
            <geometry>
                <box size="0.5 0.1 0.08"/>
            </geometry>
            <origin xyz="0.1 0 0" rpy="0 0 0"/>
        </collision>
        <inertial>
            <mass value="1.0"/>
            <origin xyz="0.1 0 0" rpy="0 0 0"/>
            <inertia ixx="0.01" ixy="0" ixz="0" iyy="0.01" iyz="0" izz="0.01"/>
        </inertial>
    </link>

    <gazebo reference="link2">
        <material>Gazebo/Red</material>
    </gazebo>

    <!-- ジョイント1（ベース→リンク1） -->
    <joint name="joint1" type="revolute">
        <parent link="base_link"/>
        <child link="link1"/>
        <origin xyz="0 0 0.15" rpy="0 0 0"/>
        <axis xyz="0 0 1"/>
        <limit lower="-3.14" upper="3.14" effort="100" velocity="1.0"/>
        <dynamics damping="0.7" friction="0.5"/>
    </joint>

    <!-- ジョイント2（リンク1→リンク2） -->
    <joint name="joint2" type="revolute">
        <parent link="link1"/>
        <child link="link2"/>
        <origin xyz="0.5 0 0.09" rpy="0 0 0"/>
        <axis xyz="0 0 1"/>
        <limit lower="-3.14" upper="3.14" effort="100" velocity="1.0"/>
        <dynamics damping="0.7" friction="0.5"/>
    </joint>
</robot> 